<?xml version="1.0"?>
<robot xmlns:xacro="http://www.ros.org/wiki/xacro">

  <!-- MACRO FOR THRUSTER UNITS  -->
  <!--
    Thruster macro with integration of joint and link. The thrusters should
    be initialized in the actuators.xacro file.
  -->
  <xacro:macro name="thruster_macro" params="robot_namespace suffix_ns thruster_id *origin simulation:=false">

    <!--
    Dummy link as place holder for the thruster frame,
    since thrusters can often be inside the collision geometry
    of the vehicle and may cause internal collisions if set otherwise
    -->
    <link name="${suffix_ns}thruster_${thruster_id}">

      <visual>
        <geometry>
          <mesh filename="package://heron_description/meshes/prop.dae" scale="1 1 1" />
        </geometry>
      </visual>

      <inertial>
        <mass value="0.001" />
        <origin xyz="0 0 0" rpy="0 0 0"/>
        <inertia ixx="0.000000017" ixy="0.0" ixz="0.0"
               iyy="0.000000017" iyz="0.0"
               izz="0.000000017" />
      </inertial>
    </link>

    <xacro:if value="${simulation}">
      <!-- Joint between thruster link and vehicle base link -->
      <joint name="${suffix_ns}thruster_${thruster_id}_joint" type="continuous">
        <xacro:insert_block name="origin" />
        <axis xyz="1 0 0" />
        <parent link="${suffix_ns}base_link" />
        <child link="${suffix_ns}thruster_${thruster_id}" />
      </joint>

      <gazebo>
        <!-- Apply thrust in the thruster link frame. The stock gazebo_ros_force
             plugin applies world-frame force, which makes the hull yaw while
             still being pushed in a stale global direction. -->
        <plugin name="${robot_namespace}thruster_${thruster_id}_model" filename="libRelativeForcePlugin.so">
          <bodyName>${suffix_ns}thruster_${thruster_id}</bodyName>
          <xacro:if value="${robot_namespace != ''}">
            <topicName>/${robot_namespace}/thrusters/${thruster_id}/input</topicName>
          </xacro:if>
          <xacro:unless value="${robot_namespace != ''}">
            <topicName>/thrusters/${thruster_id}/input</topicName>
          </xacro:unless>
        </plugin>
      </gazebo>

      <gazebo reference="${suffix_ns}thruster_${thruster_id}">
        <selfCollide>false</selfCollide>
      </gazebo>
    </xacro:if>
    <xacro:unless value="${simulation}">
      <!-- On the real robot this joint is purely decorative; it's only used to produce thrust in gazebo -->
      <joint name="${suffix_ns}thruster_${thruster_id}_joint" type="fixed">
        <xacro:insert_block name="origin" />
        <parent link="${suffix_ns}base_link" />
        <child link="${suffix_ns}thruster_${thruster_id}" />
      </joint>
    </xacro:unless>
  </xacro:macro>



</robot>
